Workbook
Name P35_: #REF!
Name P35_: #REF!
Name P35_: #REF!
Name P35_: #REF!
Name P35_: #REF!
Name P35_: #REF!
Name P35_: #REF!
Name P35_: #REF!
Name P35_: #REF!
Name P35_: #REF!
Name P35_: #REF!
Name P35_: #REF!
Name P35_: #REF!
Name P35_: #REF!
Name P35_Percent: #REF!
Name P35_Percent: #REF!
Name P35_Percent: #REF!
Name P35_Percent: #REF!
Name P35_Percent: #REF!
Name P35_Percent: #REF!
Name P35_Percent: #REF!
Name P35_Percent: #REF!
Name P35_Percent: #REF!
Name P35_Percent: #REF!
Name P35_Percent: #REF!
Name P35_Percent: #REF!
Name P35_Percent: #REF!
Name P35_Percent: #REF!
Name P35Percent: #REF!
Name P35Percent: #REF!
Name P35Percent: #REF!
Name P35Percent: #REF!
Name P35Percent: #REF!
Name P35Percent: #REF!
Name P35Percent: #REF!
Name P35Percent: #REF!
Name P35Percent: #REF!
Name P35Percent: #REF!
Name P35Percent: #REF!
Name P35Percent: #REF!
Name P35Percent: #REF!
Name P35Percent: #REF!

Sheet Log Sales Data
A1: Year | B1: Month | C1: Forest Name | D1: Grade Breakdown | E1: Lengh | F1: Species | G1: Market | H1: Customer | I1: Tonnes # | J1: Conversion Rate | K1: JAS # | L1: At mill/port Door Price | M1: Amount in NZ$ | AA1: Grade | AB1: Conversion Rate
A2: 2025 | B2: 45658 | C2: Eastfork | D2: P40 | E2: 5.9 | F2: Radiata | G2: Export | H2: FCO | I2: 200 | J2: =_xlfn.XLOOKUP(Table223[[#This Row],[Grade Breakdown]],AA:AA,AB:AB,0,0) -> 1.09 | K2: =Table223[[#This Row],[Tonnes '#]]*Table223[[#This Row],[Conversion Rate]] -> 218 | L2: 195 | M2: =Table223[[#This Row],[Tonnes '#]]*Table223[[#This Row],[At mill/port Door Price]] -> 39000 | AA2: S40 | AB2: 1.06
A3: 2025 | B3: 45658 | C3: Eastfork | D3: A | E3: 5.9 | F3: Radiata | G3: Export | H3: FCO | I3: 400 | J3: =_xlfn.XLOOKUP(Table223[[#This Row],[Grade Breakdown]],AA:AA,AB:AB,0,0) -> 1.03 | K3: =Table223[[#This Row],[Tonnes '#]]*Table223[[#This Row],[Conversion Rate]] -> 412 | L3: 127 | M3: =Table223[[#This Row],[Tonnes '#]]*Table223[[#This Row],[At mill/port Door Price]] -> 50800 | AA3: S30 | AB3: 1.03
A4: 2025 | B4: 45658 | C4: Eastfork | D4: K | E4: 5.9 | F4: Radiata | G4: Export | H4: FCO | I4: 600 | J4: =_xlfn.XLOOKUP(Table223[[#This Row],[Grade Breakdown]],AA:AA,AB:AB,0,0) -> 0.99 | K4: =Table223[[#This Row],[Tonnes '#]]*Table223[[#This Row],[Conversion Rate]] -> 594 | L4: 120 | M4: =Table223[[#This Row],[Tonnes '#]]*Table223[[#This Row],[At mill/port Door Price]] -> 72000 | AA4: S20 | AB4: 0.99
A5: 2025 | B5: 45658 | C5: Eastfork | D5: P40 | E5: 5.9 | F5: Radiata | G5: Export | H5: FCO | I5: 250 | J5: =_xlfn.XLOOKUP(Table223[[#This Row],[Grade Breakdown]],AA:AA,AB:AB,0,0) -> 1.09 | K5: =Table223[[#This Row],[Tonnes '#]]*Table223[[#This Row],[Conversion Rate]] -> 272.5 | L5: 195 | M5: =Table223[[#This Row],[Tonnes '#]]*Table223[[#This Row],[At mill/port Door Price]] -> 48750 | AA5: Domestic Pulp | AB5: 0.88
A6: 2025 | B6: 45658 | C6: Eastfork | D6: A | E6: 5.9 | F6: Radiata | G6: Export | H6: FCO | I6: 450 | J6: =_xlfn.XLOOKUP(Table223[[#This Row],[Grade Breakdown]],AA:AA,AB:AB,0,0) -> 1.03 | K6: =Table223[[#This Row],[Tonnes '#]]*Table223[[#This Row],[Conversion Rate]] -> 463.5 | L6: 127 | M6: =Table223[[#This Row],[Tonnes '#]]*Table223[[#This Row],[At mill/port Door Price]] -> 57150 | AA6: Eucalyptus | AB6: 0.95
A7: 2025 | B7: 45658 | C7: Eastfork | D7: K | E7: 5.9 | F7: Radiata | G7: Export | H7: FCO | I7: 650 | J7: =_xlfn.XLOOKUP(Table223[[#This Row],[Grade Breakdown]],AA:AA,AB:AB,0,0) -> 0.99 | K7: =Table223[[#This Row],[Tonnes '#]]*Table223[[#This Row],[Conversion Rate]] -> 643.5 | L7: 120 | M7: =Table223[[#This Row],[Tonnes '#]]*Table223[[#This Row],[At mill/port Door Price]] -> 78000 | AA7: FW | AB7: 0.95
A8: 2025 | B8: 45658 | C8: Eastfork | D8: P35 | E8: 5.9 | F8: Radiata | G8: Domestic | H8: FCO | I8: 190 | J8: =_xlfn.XLOOKUP(Table223[[#This Row],[Grade Breakdown]],AA:AA,AB:AB,0,0) -> 1.08 | K8: =Table223[[#This Row],[Tonnes '#]]*Table223[[#This Row],[Conversion Rate]] -> 205.2 | L8: 195 | M8: =Table223[[#This Row],[Tonnes '#]]*Table223[[#This Row],[At mill/port Door Price]] -> 37050 | AA8: Euc Pulp | AB8: 0.88
A9: 2025 | B9: 45658 | C9: Eastfork | D9: S30 | E9: 5.9 | F9: Radiata | G9: Domestic | H9: FCO | I9: 390 | J9: =_xlfn.XLOOKUP(Table223[[#This Row],[Grade Breakdown]],AA:AA,AB:AB,0,0) -> 1.03 | K9: =Table223[[#This Row],[Tonnes '#]]*Table223[[#This Row],[Conversion Rate]] -> 401.7 | L9: 127 | M9: =Table223[[#This Row],[Tonnes '#]]*Table223[[#This Row],[At mill/port Door Price]] -> 49530 | AA9: Binwood | AB9: 0.88
A10: 2025 | B10: 45658 | C10: Eastfork | D10: S20 | E10: 5.9 | F10: Radiata | G10: Domestic | H10: FCO | I10: 590 | J10: =_xlfn.XLOOKUP(Table223[[#This Row],[Grade Breakdown]],AA:AA,AB:AB,0,0) -> 0.99 | K10: =Table223[[#This Row],[Tonnes '#]]*Table223[[#This Row],[Conversion Rate]] -> 584.1 | L10: 120 | M10: =Table223[[#This Row],[Tonnes '#]]*Table223[[#This Row],[At mill/port Door Price]] -> 70800 | AA10: P40 | AB10: 1.09
A11: 2025 | B11: 45658 | C11: Eastfork | D11: P35 | E11: 5.9 | F11: Radiata | G11: Domestic | H11: FCO | I11: 240 | J11: =_xlfn.XLOOKUP(Table223[[#This Row],[Grade Breakdown]],AA:AA,AB:AB,0,0) -> 1.08 | K11: =Table223[[#This Row],[Tonnes '#]]*Table223[[#This Row],[Conversion Rate]] -> 259.2 | L11: 195 | M11: =Table223[[#This Row],[Tonnes '#]]*Table223[[#This Row],[At mill/port Door Price]] -> 46800 | AA11: P35 | AB11: 1.08
A12: 2025 | B12: 45658 | C12: Eastfork | D12: S30 | E12: 5.9 | F12: Radiata | G12: Domestic | H12: FCO | I12: 440 | J12: =_xlfn.XLOOKUP(Table223[[#This Row],[Grade Breakdown]],AA:AA,AB:AB,0,0) -> 1.03 | K12: =Table223[[#This Row],[Tonnes '#]]*Table223[[#This Row],[Conversion Rate]] -> 453.2 | L12: 127 | M12: =Table223[[#This Row],[Tonnes '#]]*Table223[[#This Row],[At mill/port Door Price]] -> 55880 | AA12: P30 | AB12: 1.07
A13: 2025 | B13: 45658 | C13: Eastfork | D13: S20 | E13: 5.9 | F13: Radiata | G13: Domestic | H13: FCO | I13: 640 | J13: =_xlfn.XLOOKUP(Table223[[#This Row],[Grade Breakdown]],AA:AA,AB:AB,0,0) -> 0.99 | K13: =Table223[[#This Row],[Tonnes '#]]*Table223[[#This Row],[Conversion Rate]] -> 633.6 | L13: 120 | M13: =Table223[[#This Row],[Tonnes '#]]*Table223[[#This Row],[At mill/port Door Price]] -> 76800 | AA13: AO | AB13: 1.03
A14: 2025 | J14: =_xlfn.XLOOKUP(Table223[[#This Row],[Grade Breakdown]],AA:AA,AB:AB,0,0) -> 0 | K14: =Table223[[#This Row],[Tonnes '#]]*Table223[[#This Row],[Conversion Rate]] -> 0 | M14: =Table223[[#This Row],[Tonnes '#]]*Table223[[#This Row],[At mill/port Door Price]] -> 0 | AA14: A | AB14: 1.03
A15: 2025 | J15: =_xlfn.XLOOKUP(Table223[[#This Row],[Grade Breakdown]],AA:AA,AB:AB,0,0) -> 0 | K15: =Table223[[#This Row],[Tonnes '#]]*Table223[[#This Row],[Conversion Rate]] -> 0 | M15: =Table223[[#This Row],[Tonnes '#]]*Table223[[#This Row],[At mill/port Door Price]] -> 0 | AA15: K | AB15: 0.99
A16: 2025 | J16: =_xlfn.XLOOKUP(Table223[[#This Row],[Grade Breakdown]],AA:AA,AB:AB,0,0) -> 0 | K16: =Table223[[#This Row],[Tonnes '#]]*Table223[[#This Row],[Conversion Rate]] -> 0 | M16: =Table223[[#This Row],[Tonnes '#]]*Table223[[#This Row],[At mill/port Door Price]] -> 0 | AA16: KI | AB16: 0.97
A17: 2025 | J17: =_xlfn.XLOOKUP(Table223[[#This Row],[Grade Breakdown]],AA:AA,AB:AB,0,0) -> 0 | K17: =Table223[[#This Row],[Tonnes '#]]*Table223[[#This Row],[Conversion Rate]] -> 0 | M17: =Table223[[#This Row],[Tonnes '#]]*Table223[[#This Row],[At mill/port Door Price]] -> 0 | AA17: KIS | AB17: 0.88
A18: 2025 | J18: =_xlfn.XLOOKUP(Table223[[#This Row],[Grade Breakdown]],AA:AA,AB:AB,0,0) -> 0 | K18: =Table223[[#This Row],[Tonnes '#]]*Table223[[#This Row],[Conversion Rate]] -> 0 | M18: =Table223[[#This Row],[Tonnes '#]]*Table223[[#This Row],[At mill/port Door Price]] -> 0 | AA18: KI stub | AB18: 0.97
A19: 2025 | J19: =_xlfn.XLOOKUP(Table223[[#This Row],[Grade Breakdown]],AA:AA,AB:AB,0,0) -> 0 | K19: =Table223[[#This Row],[Tonnes '#]]*Table223[[#This Row],[Conversion Rate]] -> 0 | M19: =Table223[[#This Row],[Tonnes '#]]*Table223[[#This Row],[At mill/port Door Price]] -> 0 | AA19: Scragwood | AB19: 0.95
A20: 2025 | J20: =_xlfn.XLOOKUP(Table223[[#This Row],[Grade Breakdown]],AA:AA,AB:AB,0,0) -> 0 | K20: =Table223[[#This Row],[Tonnes '#]]*Table223[[#This Row],[Conversion Rate]] -> 0 | M20: =Table223[[#This Row],[Tonnes '#]]*Table223[[#This Row],[At mill/port Door Price]] -> 0 | AA20: CF+ | AB20: 1.03
A21: 2025 | J21: =_xlfn.XLOOKUP(Table223[[#This Row],[Grade Breakdown]],AA:AA,AB:AB,0,0) -> 0 | K21: =Table223[[#This Row],[Tonnes '#]]*Table223[[#This Row],[Conversion Rate]] -> 0 | M21: =Table223[[#This Row],[Tonnes '#]]*Table223[[#This Row],[At mill/port Door Price]] -> 0 | AA21: CF- | AB21: 0.99
A22: 2025 | J22: =_xlfn.XLOOKUP(Table223[[#This Row],[Grade Breakdown]],AA:AA,AB:AB,0,0) -> 0 | K22: =Table223[[#This Row],[Tonnes '#]]*Table223[[#This Row],[Conversion Rate]] -> 0 | M22: =Table223[[#This Row],[Tonnes '#]]*Table223[[#This Row],[At mill/port Door Price]] -> 0 | AA22: CM | AB22: 0.97
A23: 2025 | J23: =_xlfn.XLOOKUP(Table223[[#This Row],[Grade Breakdown]],AA:AA,AB:AB,0,0) -> 0 | K23: =Table223[[#This Row],[Tonnes '#]]*Table223[[#This Row],[Conversion Rate]] -> 0 | M23: =Table223[[#This Row],[Tonnes '#]]*Table223[[#This Row],[At mill/port Door Price]] -> 0 | AA23: Euc A | AB23: 0.95
A24: 2025 | J24: =_xlfn.XLOOKUP(Table223[[#This Row],[Grade Breakdown]],AA:AA,AB:AB,0,0) -> 0 | K24: =Table223[[#This Row],[Tonnes '#]]*Table223[[#This Row],[Conversion Rate]] -> 0 | M24: =Table223[[#This Row],[Tonnes '#]]*Table223[[#This Row],[At mill/port Door Price]] -> 0 | AA24: Euc K | AB24: 0.93
A25: 2025 | J25: =_xlfn.XLOOKUP(Table223[[#This Row],[Grade Breakdown]],AA:AA,AB:AB,0,0) -> 0 | K25: =Table223[[#This Row],[Tonnes '#]]*Table223[[#This Row],[Conversion Rate]] -> 0 | M25: =Table223[[#This Row],[Tonnes '#]]*Table223[[#This Row],[At mill/port Door Price]] -> 0
A26: 2025 | J26: =_xlfn.XLOOKUP(Table223[[#This Row],[Grade Breakdown]],AA:AA,AB:AB,0,0) -> 0 | K26: =Table223[[#This Row],[Tonnes '#]]*Table223[[#This Row],[Conversion Rate]] -> 0 | M26: =Table223[[#This Row],[Tonnes '#]]*Table223[[#This Row],[At mill/port Door Price]] -> 0
A27: 2025 | J27: =_xlfn.XLOOKUP(Table223[[#This Row],[Grade Breakdown]],AA:AA,AB:AB,0,0) -> 0 | K27: =Table223[[#This Row],[Tonnes '#]]*Table223[[#This Row],[Conversion Rate]] -> 0 | M27: =Table223[[#This Row],[Tonnes '#]]*Table223[[#This Row],[At mill/port Door Price]] -> 0
A28: 2025 | J28: =_xlfn.XLOOKUP(Table223[[#This Row],[Grade Breakdown]],AA:AA,AB:AB,0,0) -> 0 | K28: =Table223[[#This Row],[Tonnes '#]]*Table223[[#This Row],[Conversion Rate]] -> 0 | M28: =Table223[[#This Row],[Tonnes '#]]*Table223[[#This Row],[At mill/port Door Price]] -> 0
A29: 2025 | J29: =_xlfn.XLOOKUP(Table223[[#This Row],[Grade Breakdown]],AA:AA,AB:AB,0,0) -> 0 | K29: =Table223[[#This Row],[Tonnes '#]]*Table223[[#This Row],[Conversion Rate]] -> 0 | M29: =Table223[[#This Row],[Tonnes '#]]*Table223[[#This Row],[At mill/port Door Price]] -> 0
A30: 2025 | J30: =_xlfn.XLOOKUP(Table223[[#This Row],[Grade Breakdown]],AA:AA,AB:AB,0,0) -> 0 | K30: =Table223[[#This Row],[Tonnes '#]]*Table223[[#This Row],[Conversion Rate]] -> 0 | M30: =Table223[[#This Row],[Tonnes '#]]*Table223[[#This Row],[At mill/port Door Price]] -> 0
A31: 2025 | J31: =_xlfn.XLOOKUP(Table223[[#This Row],[Grade Breakdown]],AA:AA,AB:AB,0,0) -> 0 | K31: =Table223[[#This Row],[Tonnes '#]]*Table223[[#This Row],[Conversion Rate]] -> 0 | M31: =Table223[[#This Row],[Tonnes '#]]*Table223[[#This Row],[At mill/port Door Price]] -> 0
A32: 2025 | J32: =_xlfn.XLOOKUP(Table223[[#This Row],[Grade Breakdown]],AA:AA,AB:AB,0,0) -> 0 | K32: =Table223[[#This Row],[Tonnes '#]]*Table223[[#This Row],[Conversion Rate]] -> 0 | M32: =Table223[[#This Row],[Tonnes '#]]*Table223[[#This Row],[At mill/port Door Price]] -> 0
A33: 2025 | J33: =_xlfn.XLOOKUP(Table223[[#This Row],[Grade Breakdown]],AA:AA,AB:AB,0,0) -> 0 | K33: =Table223[[#This Row],[Tonnes '#]]*Table223[[#This Row],[Conversion Rate]] -> 0 | M33: =Table223[[#This Row],[Tonnes '#]]*Table223[[#This Row],[At mill/port Door Price]] -> 0
A34: 2025 | J34: =_xlfn.XLOOKUP(Table223[[#This Row],[Grade Breakdown]],AA:AA,AB:AB,0,0) -> 0 | K34: =Table223[[#This Row],[Tonnes '#]]*Table223[[#This Row],[Conversion Rate]] -> 0 | M34: =Table223[[#This Row],[Tonnes '#]]*Table223[[#This Row],[At mill/port Door Price]] -> 0
A35: 2025 | J35: =_xlfn.XLOOKUP(Table223[[#This Row],[Grade Breakdown]],AA:AA,AB:AB,0,0) -> 0 | K35: =Table223[[#This Row],[Tonnes '#]]*Table223[[#This Row],[Conversion Rate]] -> 0 | M35: =Table223[[#This Row],[Tonnes '#]]*Table223[[#This Row],[At mill/port Door Price]] -> 0
A36: 2025 | J36: =_xlfn.XLOOKUP(Table223[[#This Row],[Grade Breakdown]],AA:AA,AB:AB,0,0) -> 0 | K36: =Table223[[#This Row],[Tonnes '#]]*Table223[[#This Row],[Conversion Rate]] -> 0 | M36: =Table223[[#This Row],[Tonnes '#]]*Table223[[#This Row],[At mill/port Door Price]] -> 0
... A57: 2025 | J57: =_xlfn.XLOOKUP(Table223[[#This Row],[Grade Breakdown]],AA:AA,AB:AB,0,0) -> 0 | K57: =Table223[[#This Row],[Tonnes '#]]*Table223[[#This Row],[Conversion Rate]] -> 0 | M57: =Table223[[#This Row],[Tonnes '#]]*Table223[[#This Row],[At mill/port Door Price]] -> 0

Sheet Eastfork Budget
C1: 2025 | D1: Input
B2: Eastfork | H2: Estimated Tonnes (ha)
B3: PRODUCTION & RATE | G3: Total Monthly Working Days | I3: =SUM(J5:U5)+SUM(J8:U8)+SUM(J11:U11) -> 0 | J3: 45658 | K3: 45689 | L3: 45717 | M3: 45748 | N3: 45778 | O3: 45809 | P3: 45839 | Q3: 45870 | R3: 45901 | S3: 45931 | T3: 45962 | U3: 45992 | W3: Total
G4: Groundbase | H4: Daily production | I4: =IFERROR((J4*J5+K4*K5+L4*L5+M4*M5+N4*N5+O4*O5+P4*P5+Q4*Q5+R4*R5+S4*S5+T4*T5+U4*U5)/$W$16,0) -> 0
H5: Days worked
H6: Harvesting Rate
G7: Roadline | H7: Daily production | I7: =IFERROR((J7*J8+K7*K8+L7*L8+M7*M8+N7*N8+O7*O8+P7*P8+Q7*Q8+R7*R8+S7*S8+T7*T8+U7*U8)/$W$16,0) -> 0
H8: Days worked
H9: Harvesting Rate
G10: Hauler | H10: Daily production | I10: =IFERROR((J10*J11+K10*K11+L10*L11+M10*M11+N10*N11+O10*O11+P10*P11+Q10*Q11+R10*R11+S10*S11+T10*T11+U10*U11)/$W$16,0) -> 0
H11: Days worked
H12: Harvesting Rate
G13: Average | H13: Harvesting Rate | I13: =SUM(I4:I12) -> 0 | J13: =IFERROR((J4*J5*J6+J7*J8*J9+J10*J11*J12)/J16,0) -> 0 | K13: =IFERROR((K4*K5*K6+K7*K8*K9+K10*K11*K12)/K16,0) -> 0 | L13: =IFERROR((L4*L5*L6+L7*L8*L9+L10*L11*L12)/L16,0) -> 0 | M13: =IFERROR((M4*M5*M6+M7*M8*M9+M10*M11*M12)/M16,0) -> 0 | N13: =IFERROR((N4*N5*N6+N7*N8*N9+N10*N11*N12)/N16,0) -> 0 | O13: =IFERROR((O4*O5*O6+O7*O8*O9+O10*O11*O12)/O16,0) -> 0 | P13: =IFERROR((P4*P5*P6+P7*P8*P9+P10*P11*P12)/P16,0) -> 0 | Q13: =IFERROR((Q4*Q5*Q6+Q7*Q8*Q9+Q10*Q11*Q12)/Q16,0) -> 0 | ... U13: =IFERROR((U4*U5*U6+U7*U8*U9+U10*U11*U12)/U16,0) -> 0 | W13: =I3 -> 0 | X13: Monthly Working Days
G14: Average | H14: Daily production | J14: =J4+J7+J10 -> 0 | K14: =K4+K7+K10 -> 0 | L14: =L4+L7+L10 -> 0 | M14: =M4+M7+M10 -> 0 | N14: =N4+N7+N10 -> 0 | O14: =O4+O7+O10 -> 0 | P14: =P4+P7+P10 -> 0 | Q14: =Q4+Q7+Q10 -> 0 | ... U14: =U4+U7+U10 -> 0 | W14: =IF(W16=0,0,W16/W15) -> 0 | X14: =H2 -> Estimated Tonnes (ha)
G15: Total | H15: Hectare (ha) | J15: =IFERROR(J16/$I$2,0) -> 0 | K15: =IFERROR(K16/$I$2,0) -> 0 | L15: =IFERROR(L16/$I$2,0) -> 0 | M15: =IFERROR(M16/$I$2,0) -> 0 | N15: =IFERROR(N16/$I$2,0) -> 0 | O15: =IFERROR(O16/$I$2,0) -> 0 | P15: =IFERROR(P16/$I$2,0) -> 0 | Q15: =IFERROR(Q16/$I$2,0) -> 0 | ... U15: =IFERROR(U16/$I$2,0) -> 0 | W15: =SUM(J15:U15) -> 0 | X15: =H15 -> Hectare (ha)
G16: Total | H16: Tonnes Harvested | J16: =IFERROR((J4*J5+J7*J8+J10*J11),0) -> 0 | K16: =IFERROR((K4*K5+K7*K8+K10*K11),0) -> 0 | L16: =IFERROR((L4*L5+L7*L8+L10*L11),0) -> 0 | M16: =IFERROR((M4*M5+M7*M8+M10*M11),0) -> 0 | N16: =IFERROR((N4*N5+N7*N8+N10*N11),0) -> 0 | O16: =IFERROR((O4*O5+O7*O8+O10*O11),0) -> 0 | P16: =IFERROR((P4*P5+P7*P8+P10*P11),0) -> 0 | Q16: =IFERROR((Q4*Q5+Q7*Q8+Q10*Q11),0) -> 0 | ... U16: =IFERROR((U4*U5+U7*U8+U10*U11),0) -> 0 | W16: =SUM(J16:U16) -> 0 | X16: =H16 -> Tonnes Harvested
W17: =W16/W15 -> #DIV/0! | X17: Vol/ha
B18: REVENUE
B19: Grade | C19: Grade Mix % | D19: Conversion Rate | E19: Sale unit | F19: Sale unit/Vol | G19: Price/Unit | H19: TOTAL | J19: 45658 | K19: 45689 | L19: 45717 | M19: 45748 | N19: 45778 | O19: 45809 | P19: 45839 | Q19: 45870 | R19: 45901 | S19: 45931 | T19: 45962 | U19: 45992
B20: P35 | C20: 0.11412433 | D20: 1 | E20: Tonnes | F20: =IFERROR(H20/G20,0) -> 0 | H20: =SUM(J20:U20) -> 0 | J20: =J16*$C20*$D20*$G20 -> 0 | K20: =K16*$C$20*$D$20*$G$20 -> 0 | L20: =L16*$C$20*$D$20*$G$20 -> 0 | M20: =M16*$C$20*$D$20*$G$20 -> 0 | N20: =N16*$C$20*$D$20*$G$20 -> 0 | O20: =O16*$C$20*$D$20*$G$20 -> 0 | P20: =P16*$C$20*$D$20*$G$20 -> 0 | Q20: =Q16*$C$20*$D$20*$G$20 -> 0 | R20: =R16*$C$20*$D$20*$G$20 -> 0 | ... U20: =U16*$C$20*$D$20*$G$20 -> 0 | W20: =$W$17*C20 -> #DIV/0! | X20: =B20 -> P35
B21: S30 | C21: 0.07 | D21: 1 | E21: Tonnes | F21: =IFERROR(H21/G21,0) -> 0 | H21: =SUM(J21:U21) -> 0 | J21: =J16*$C$21*$D$21*$G$21 -> 0 | K21: =K16*$C$21*$D$21*$G$21 -> 0 | L21: =L16*$C$21*$D$21*$G$21 -> 0 | M21: =M16*$C$21*$D$21*$G$21 -> 0 | N21: =N16*$C$21*$D$21*$G$21 -> 0 | O21: =O16*$C$21*$D$21*$G$21 -> 0 | P21: =P16*$C$21*$D$21*$G$21 -> 0 | Q21: =Q16*$C$21*$D$21*$G$21 -> 0 | ... U21: =U16*$C$21*$D$21*$G$21 -> 0 | W21: =$W$17*C21 -> #DIV/0! | X21: =B21 -> S30
B22: S20 | C22: 0 | D22: 1 | E22: Tonnes | F22: =IFERROR(H22/G22,0) -> 0 | H22: =SUM(J22:U22) -> 0 | J22: =J16*$C$22*$D$22*$G$22 -> 0 | K22: =K16*$C$22*$D$22*$G$22 -> 0 | L22: =L16*$C$22*$D$22*$G$22 -> 0 | M22: =M16*$C$22*$D$22*$G$22 -> 0 | N22: =N16*$C$22*$D$22*$G$22 -> 0 | O22: =O16*$C$22*$D$22*$G$22 -> 0 | P22: =P16*$C$22*$D$22*$G$22 -> 0 | Q22: =Q16*$C$22*$D$22*$G$22 -> 0 | ... U22: =U16*$C$22*$D$22*$G$22 -> 0 | W22: =$W$17*C22 -> #DIV/0! | X22: =B22 -> S20
B23: Domestic Pulp | C23: 0.05 | D23: 1 | E23: Tonnes | F23: =IFERROR(H23/G23,0) -> 0 | H23: =SUM(J23:U23) -> 0 | J23: =J16*$C$23*$D$23*$G$23 -> 0 | K23: =K16*$C$23*$D$23*$G$23 -> 0 | L23: =L16*$C$23*$D$23*$G$23 -> 0 | M23: =M16*$C$23*$D$23*$G$23 -> 0 | N23: =N16*$C$23*$D$23*$G$23 -> 0 | O23: =O16*$C$23*$D$23*$G$23 -> 0 | P23: =P16*$C$23*$D$23*$G$23 -> 0 | Q23: =Q16*$C$23*$D$23*$G$23 -> 0 | ... U23: =U16*$C$23*$D$23*$G$23 -> 0 | W23: =$W$17*C23 -> #DIV/0! | X23: =B23 -> Domestic Pulp
B24: Eucalyptus | C24: 0 | D24: 1 | E24: Tonnes | F24: =IFERROR(H24/G24,0) -> 0 | H24: =SUM(J24:U24) -> 0 | J24: =J16*$C$24*$D$24*$G$24 -> 0 | K24: =K16*$C$24*$D$24*$G$24 -> 0 | L24: =L16*$C$24*$D$24*$G$24 -> 0 | M24: =M16*$C$24*$D$24*$G$24 -> 0 | N24: =N16*$C$24*$D$24*$G$24 -> 0 | O24: =O16*$C$24*$D$24*$G$24 -> 0 | P24: =P16*$C$24*$D$24*$G$24 -> 0 | Q24: =Q16*$C$24*$D$24*$G$24 -> 0 | ... U24: =U16*$C$24*$D$24*$G$24 -> 0 | W24: =$W$17*C24 -> #DIV/0! | X24: =B24 -> Eucalyptus
B25: FW | C25: 0 | D25: 1 | E25: Tonnes | F25: =IFERROR(H25/G25,0) -> 0 | H25: =SUM(J25:U25) -> 0 | J25: =J16*$C$25*$D$25*$G$25 -> 0 | K25: =K16*$C$25*$D$25*$G$25 -> 0 | L25: =L16*$C$25*$D$25*$G$25 -> 0 | M25: =M16*$C$25*$D$25*$G$25 -> 0 | N25: =N16*$C$25*$D$25*$G$25 -> 0 | O25: =O16*$C$25*$D$25*$G$25 -> 0 | P25: =P16*$C$25*$D$25*$G$25 -> 0 | Q25: =Q16*$C$25*$D$25*$G$25 -> 0 | ... U25: =U16*$C$25*$D$25*$G$25 -> 0 | W25: =$W$17*C25 -> #DIV/0! | X25: =B25 -> FW
B26: Euc Pulp | C26: 0 | D26: 1 | E26: Tonnes | F26: =IFERROR(H26/G26,0) -> 0 | H26: =SUM(J26:U26) -> 0 | J26: =J16*$C$26*$D$26*$G$26 -> 0 | K26: =K16*$C$26*$D$26*$G$26 -> 0 | L26: =L16*$C$26*$D$26*$G$26 -> 0 | M26: =M16*$C$26*$D$26*$G$26 -> 0 | N26: =N16*$C$26*$D$26*$G$26 -> 0 | O26: =O16*$C$26*$D$26*$G$26 -> 0 | P26: =P16*$C$26*$D$26*$G$26 -> 0 | Q26: =Q16*$C$26*$D$26*$G$26 -> 0 | ... U26: =U16*$C$26*$D$26*$G$26 -> 0 | W26: =$W$17*C26 -> #DIV/0! | X26: =B26 -> Euc Pulp
B27: Binwood | C27: 0 | D27: 1 | E27: Tonnes | F27: =IFERROR(H27/G27,0) -> 0 | H27: =SUM(J27:U27) -> 0 | J27: =J16*$C$27*$D$27*$G$27 -> 0 | K27: =K16*$C$27*$D$27*$G$27 -> 0 | L27: =L16*$C$27*$D$27*$G$27 -> 0 | M27: =M16*$C$27*$D$27*$G$27 -> 0 | N27: =N16*$C$27*$D$27*$G$27 -> 0 | O27: =O16*$C$27*$D$27*$G$27 -> 0 | P27: =P16*$C$27*$D$27*$G$27 -> 0 | Q27: =Q16*$C$27*$D$27*$G$27 -> 0 | ... U27: =U16*$C$27*$D$27*$G$27 -> 0 | W27: =$W$17*C27 -> #DIV/0! | X27: =B27 -> Binwood
B28: Spare Grade | C28: 0 | E28: Tonnes | F28: =IFERROR(H28/G28/D28,0) -> 0 | H28: =SUM(J28:U28) -> 0 | J28: =J16*$C$28*$D$28*$G$28 -> 0 | K28: =K16*$C$28*$D$28*$G$28 -> 0 | L28: =L16*$C$28*$D$28*$G$28 -> 0 | M28: =M16*$C$28*$D$28*$G$28 -> 0 | N28: =N16*$C$28*$D$28*$G$28 -> 0 | O28: =O16*$C$28*$D$28*$G$28 -> 0 | P28: =P16*$C$28*$D$28*$G$28 -> 0 | Q28: =Q16*$C$28*$D$28*$G$28 -> 0 | ... U28: =U16*$C$28*$D$28*$G$28 -> 0 | W28: =$W$17*C28 -> #DIV/0! | X28: =B28 -> Spare Grade
B29: P40 | C29: 0 | D29: 1 | E29: JAS | F29: =IFERROR(H29/G29/D29,0) -> 0 | H29: =SUM(J29:U29) -> 0 | J29: =J16*$C$29*$D$29*$G$29 -> 0 | K29: =K16*$C$29*$D$29*$G$29 -> 0 | L29: =L16*$C$29*$D$29*$G$29 -> 0 | M29: =M16*$C$29*$D$29*$G$29 -> 0 | N29: =N16*$C$29*$D$29*$G$29 -> 0 | O29: =O16*$C$29*$D$29*$G$29 -> 0 | P29: =P16*$C$29*$D$29*$G$29 -> 0 | Q29: =Q16*$C$29*$D$29*$G$29 -> 0 | ... U29: =U16*$C$29*$D$29*$G$29 -> 0 | W29: =$W$17*C29 -> #DIV/0! | X29: =B29 -> P40
B30: P30 | C30: 0.0019336678 | D30: 1.0288961 | E30: JAS | F30: =IFERROR(H30/G30/D30,0) -> 0 | H30: =SUM(J30:U30) -> 0 | J30: =J16*$C$30*$D$30*$G$30 -> 0 | K30: =K16*$C$30*$D$30*$G$30 -> 0 | L30: =L16*$C$30*$D$30*$G$30 -> 0 | M30: =M16*$C$30*$D$30*$G$30 -> 0 | N30: =N16*$C$30*$D$30*$G$30 -> 0 | O30: =O16*$C$30*$D$30*$G$30 -> 0 | P30: =P16*$C$30*$D$30*$G$30 -> 0 | Q30: =Q16*$C$30*$D$30*$G$30 -> 0 | ... U30: =U16*$C$30*$D$30*$G$30 -> 0 | W30: =$W$17*C30 -> #DIV/0! | X30: =B30 -> P30
B31: AO | C31: 0.15 | D31: 1.04 | E31: JAS | F31: =IFERROR(H31/G31/D31,0) -> 0 | H31: =SUM(J31:U31) -> 0 | J31: =J16*$C$31*$D$31*$G$31 -> 0 | K31: =K16*$C$31*$D$31*$G$31 -> 0 | L31: =L16*$C$31*$D$31*$G$31 -> 0 | M31: =M16*$C$31*$D$31*$G$31 -> 0 | N31: =N16*$C$31*$D$31*$G$31 -> 0 | O31: =O16*$C$31*$D$31*$G$31 -> 0 | P31: =P16*$C$31*$D$31*$G$31 -> 0 | Q31: =Q16*$C$31*$D$31*$G$31 -> 0 | ... U31: =U16*$C$31*$D$31*$G$31 -> 0 | W31: =$W$17*C31 -> #DIV/0! | X31: =B31 -> AO
B32: A | C32: 0.28 | D32: 1.01 | E32: JAS | F32: =IFERROR(H32/G32/D32,0) -> 0 | H32: =SUM(J32:U32) -> 0 | J32: =J16*$C$32*$D$32*$G$32 -> 0 | K32: =K16*$C$32*$D$32*$G$32 -> 0 | L32: =L16*$C$32*$D$32*$G$32 -> 0 | M32: =M16*$C$32*$D$32*$G$32 -> 0 | N32: =N16*$C$32*$D$32*$G$32 -> 0 | O32: =O16*$C$32*$D$32*$G$32 -> 0 | P32: =P16*$C$32*$D$32*$G$32 -> 0 | Q32: =Q16*$C$32*$D$32*$G$32 -> 0 | ... U32: =U16*$C$32*$D$32*$G$32 -> 0 | W32: =$W$17*C32 -> #DIV/0! | X32: =B32 -> A
B33: K | C33: 0.20870336 | D33: 0.96 | E33: JAS | F33: =IFERROR(H33/G33/D33,0) -> 0 | H33: =SUM(J33:U33) -> 0 | J33: =J16*$C$33*$D$33*$G$33 -> 0 | K33: =K16*$C$33*$D$33*$G$33 -> 0 | L33: =L16*$C$33*$D$33*$G$33 -> 0 | M33: =M16*$C$33*$D$33*$G$33 -> 0 | N33: =N16*$C$33*$D$33*$G$33 -> 0 | O33: =O16*$C$33*$D$33*$G$33 -> 0 | P33: =P16*$C$33*$D$33*$G$33 -> 0 | Q33: =Q16*$C$33*$D$33*$G$33 -> 0 | ... U33: =U16*$C$33*$D$33*$G$33 -> 0 | W33: =$W$17*C33 -> #DIV/0! | X33: =B33 -> K
B34: KI | C34: 0.025784396 | D34: 0.97 | E34: JAS | F34: =IFERROR(H34/G34/D34,0) -> 0 | H34: =SUM(J34:U34) -> 0 | J34: =J16*$C$34*$D$34*$G$34 -> 0 | K34: =K16*$C$34*$D$34*$G$34 -> 0 | L34: =L16*$C$34*$D$34*$G$34 -> 0 | M34: =M16*$C$34*$D$34*$G$34 -> 0 | N34: =N16*$C$34*$D$34*$G$34 -> 0 | O34: =O16*$C$34*$D$34*$G$34 -> 0 | P34: =P16*$C$34*$D$34*$G$34 -> 0 | Q34: =Q16*$C$34*$D$34*$G$34 -> 0 | ... U34: =U16*$C$34*$D$34*$G$34 -> 0 | W34: =$W$17*C34 -> #DIV/0! | X34: =B34 -> KI
B35: KIS | C35: 0.1017521 | D35: 0.92 | E35: JAS | F35: =IFERROR(H35/G35/D35,0) -> 0 | H35: =SUM(J35:U35) -> 0 | J35: =J16*$C$35*$D$35*$G$35 -> 0 | K35: =K16*$C$35*$D$35*$G$35 -> 0 | L35: =L16*$C$35*$D$35*$G$35 -> 0 | M35: =M16*$C$35*$D$35*$G$35 -> 0 | N35: =N16*$C$35*$D$35*$G$35 -> 0 | O35: =O16*$C$35*$D$35*$G$35 -> 0 | P35: =P16*$C$35*$D$35*$G$35 -> 0 | Q35: =Q16*$C$35*$D$35*$G$35 -> 0 | ... U35: =U16*$C$35*$D$35*$G$35 -> 0 | W35: =$W$17*C35 -> #DIV/0! | X35: =B35 -> KIS
B36: KI stub | E36: JAS | F36: =IFERROR(H36/G36/D36,0) -> 0 | H36: =SUM(J36:U36) -> 0 | J36: =J16*$C$36*$D$36*$G$36 -> 0 | K36: =K16*$C$36*$D$36*$G$36 -> 0 | L36: =L16*$C$36*$D$36*$G$36 -> 0 | M36: =M16*$C$36*$D$36*$G$36 -> 0 | N36: =N16*$C$36*$D$36*$G$36 -> 0 | O36: =O16*$C$36*$D$36*$G$36 -> 0 | P36: =P16*$C$36*$D$36*$G$36 -> 0 | Q36: =Q16*$C$36*$D$36*$G$36 -> 0 | ... U36: =U16*$C$36*$D$36*$G$36 -> 0 | W36: =$W$17*C36 -> #DIV/0! | X36: =B36 -> KI stub
B37: CF+ | E37: JAS | F37: =IFERROR(H37/G37/D37,0) -> 0 | H37: =SUM(J37:U37) -> 0 | J37: =J16*$C$37*$D$37*$G$37 -> 0 | K37: =K16*$C$37*$D$37*$G$37 -> 0 | L37: =L16*$C$37*$D$37*$G$37 -> 0 | M37: =M16*$C$37*$D$37*$G$37 -> 0 | N37: =N16*$C$37*$D$37*$G$37 -> 0 | O37: =O16*$C$37*$D$37*$G$37 -> 0 | P37: =P16*$C$37*$D$37*$G$37 -> 0 | Q37: =Q16*$C$37*$D$37*$G$37 -> 0 | ... U37: =U16*$C$37*$D$37*$G$37 -> 0 | W37: =$W$17*C37 -> #DIV/0! | X37: =B37 -> CF+
B38: CF- | E38: JAS | F38: =IFERROR(H38/G38/D38,0) -> 0 | H38: =SUM(J38:U38) -> 0 | J38: =J16*$C$38*$D$38*$G$38 -> 0 | K38: =K16*$C$38*$D$38*$G$38 -> 0 | L38: =L16*$C$38*$D$38*$G$38 -> 0 | M38: =M16*$C$38*$D$38*$G$38 -> 0 | N38: =N16*$C$38*$D$38*$G$38 -> 0 | O38: =O16*$C$38*$D$38*$G$38 -> 0 | P38: =P16*$C$38*$D$38*$G$38 -> 0 | Q38: =Q16*$C$38*$D$38*$G$38 -> 0 | ... U38: =U16*$C$38*$D$38*$G$38 -> 0 | W38: =$W$17*C38 -> #DIV/0! | X38: =B38 -> CF-
B39: CM | E39: JAS | F39: =IFERROR(H39/G39/D39,0) -> 0 | H39: =SUM(J39:U39) -> 0 | J39: =J16*$C$39*$D$39*$G$39 -> 0 | K39: =K16*$C$39*$D$39*$G$39 -> 0 | L39: =L16*$C$39*$D$39*$G$39 -> 0 | M39: =M16*$C$39*$D$39*$G$39 -> 0 | N39: =N16*$C$39*$D$39*$G$39 -> 0 | O39: =O16*$C$39*$D$39*$G$39 -> 0 | P39: =P16*$C$39*$D$39*$G$39 -> 0 | Q39: =Q16*$C$39*$D$39*$G$39 -> 0 | ... U39: =U16*$C$39*$D$39*$G$39 -> 0 | W39: =$W$17*C39 -> #DIV/0! | X39: =B39 -> CM
B40: Euc A | E40: JAS | F40: =IFERROR(H40/G40/D40,0) -> 0 | H40: =SUM(J40:U40) -> 0 | J40: =J16*$C$40*$D$40*$G$40 -> 0 | K40: =K16*$C$40*$D$40*$G$40 -> 0 | L40: =L16*$C$40*$D$40*$G$40 -> 0 | M40: =M16*$C$40*$D$40*$G$40 -> 0 | N40: =N16*$C$40*$D$40*$G$40 -> 0 | O40: =O16*$C$40*$D$40*$G$40 -> 0 | P40: =P16*$C$40*$D$40*$G$40 -> 0 | Q40: =Q16*$C$40*$D$40*$G$40 -> 0 | ... U40: =U16*$C$40*$D$40*$G$40 -> 0 | W40: =$W$17*C40 -> #DIV/0! | X40: =B40 -> Euc A
...

Sheet Eastfork Actual
C1: ='Eastfork Budget'!C1 -> 2025 | D1: Input
B2: ='Eastfork Budget'!B2 -> Eastfork | H2: Estimated Tonnes (ha)
B3: PRODUCTION & RATE | G3: Total Monthly Working Days | I3: =IF(NOT(ISBLANK(J5)), J5, IF(NOT(ISBLANK(J8)), J8, IF(NOT(ISBLANK(J11)), J11, 0)))+IF(NOT(ISBLANK(K5)), K5, IF(NOT(ISBLANK(K8)), K8, IF(NOT(ISBLANK(K11)), K11, 0)))+IF(NOT(ISBLANK(L5)), L5, IF(NOT(ISBLANK(L8)), L8, IF(NOT(ISBLANK(L11)), L11, 0)))+IF(NOT(ISBLANK(M5)), M5, IF(NOT(ISBLANK(M8)), M8, IF(NOT(ISBLANK(M11)), M11, 0)))+IF(NOT(ISBLANK(N5)), N5, IF(NOT(ISBLANK(N8)), N8, IF(NOT(ISBLANK(N11)), N11, 0)))+IF(NOT(ISBLANK(O5)), O5, IF(NOT(ISBLANK(O8)), O8, IF(NOT(ISBLANK(O11)), O11, 0)))+IF(NOT(ISBLANK(P5)), P5, IF(NOT(ISBLANK(P8)), P8, IF(NOT(ISBLANK(P11)), P11, 0)))+IF(NOT(ISBLANK(Q5)), Q5, IF(NOT(ISBLANK(Q8)), Q8, IF(NOT(ISBLANK(Q11)), Q11, 0)))+IF(NOT(ISBLANK(R5)), R5, IF(NOT(ISBLANK(R8)), R8, IF(NOT(ISBLANK(R11)), R11, 0)))+IF(NOT(ISBLANK(S5)), S5, IF(NOT(ISBLANK(S8)), S8, IF(NOT(ISBLANK(S11)), S11, 0)))+IF(NOT(ISBLANK(T5)), T5, IF(NOT(ISBLANK(T8)), T8, IF(NOT(ISBLANK(T11)), T11, 0)))+IF(NOT(ISBLANK(U5)), U5, IF(NOT(ISBLANK(U8)), U8, IF(NOT(ISBLANK(U11)), U11, 0))) -> 0 | J3: 45658 | K3: 45689 | L3: 45717 | M3: 45748 | N3: 45778 | O3: 45809 | P3: 45839 | Q3: 45870 | R3: 45901 | S3: 45931 | T3: 45962 | U3: 45992
G4: Roadline | H4: Total production | I4: =IFERROR(SUM(J4:U4)/$W$16,0) -> 0
H5: Days worked
H6: Harvesting Rate
G7: Groundbase | H7: Total production | I7: =IFERROR(SUM(J7:U7)/$W$16,0) -> 0
H8: Days worked
H9: Harvesting Rate
G10: Hauler | H10: Total production | I10: =IFERROR(SUM(J10:U10)/$W$16,0) -> 0
H11: Days worked
H12: Harvesting Rate
G13: Total | H13: Harvested Tonnes | I13: =SUM(I4:I12) -> 0 | J13: =J4+J7+J10 -> 0 | K13: =K4+K7+K10 -> 0 | L13: =L4+L7+L10 -> 0 | M13: =M4+M7+M10 -> 0 | N13: =N4+N7+N10 -> 0 | O13: =O4+O7+O10 -> 0 | P13: =P4+P7+P10 -> 0 | Q13: =Q4+Q7+Q10 -> 0 | ... U13: =U4+U7+U10 -> 0 | W13: =I3 -> 0 | X13: Monthly Working Days
H14: Variance Tones | J14: =J13-J16 -> 0 | K14: =K13-K16 -> 0 | L14: =L13-L16 -> 0 | M14: =M13-M16 -> 0 | N14: =N13-N16 -> 0 | O14: =O13-O16 -> 0 | P14: =P13-P16 -> 0 | Q14: =Q13-Q16 -> 0 | ... U14: =U13-U16 -> 0 | W14: =SUM(J14:U14) -> 0 | X14: =H14 -> Variance Tones
G15: Total | H15: Hectare (ha) | J15: =IFERROR(J13/$I$2,0) -> 0 | K15: =IFERROR(K13/$I$2,0) -> 0 | L15: =IFERROR(L13/$I$2,0) -> 0 | M15: =IFERROR(M13/$I$2,0) -> 0 | N15: =IFERROR(N13/$I$2,0) -> 0 | O15: =IFERROR(O13/$I$2,0) -> 0 | P15: =IFERROR(P13/$I$2,0) -> 0 | Q15: =IFERROR(Q13/$I$2,0) -> 0 | ... U15: =IFERROR(U13/$I$2,0) -> 0 | W15: =SUM(J15:U15) -> 0 | X15: =H15 -> Hectare (ha)
G16: Total | H16: Invoice Tonnes | J16: =Volume_1!D27 -> 0 | K16: =Volume_1!H27 -> 0 | L16: =Volume_1!L27 -> 0 | M16: =Volume_1!P27 -> 0 | N16: =Volume_1!T27 -> 0 | O16: =Volume_1!X27 -> 0 | P16: =Volume_1!AB27 -> 0 | Q16: =Volume_1!AF27 -> 0 | R16: =Volume_1!AJ27 -> 0 | S16: =Volume_1!AN27 -> 0 | T16: =Volume_1!AR27 -> 0 | U16: =Volume_1!AV27 -> 0 | W16: =SUM(J16:U16) -> 0 | X16: =H16 -> Invoice Tonnes
B18: REVENUE
B19: Grade | C19: Grade Mix % | D19: Conversion Rate | E19: Sale unit | F19: Sale unit/t | G19: Price/Unit | H19: TOTAL | J19: 45658 | K19: 45689 | L19: 45717 | M19: 45748 | N19: 45778 | O19: 45809 | P19: 45839 | Q19: 45870 | R19: 45901 | S19: 45931 | T19: 45962 | U19: 45992
A20: Domestic | B20: P35 | C20: =IFERROR(F20/$F$46,0) -> 0.08531746 | D20: =_xlfn.XLOOKUP(B20,'Log Sales Data'!AA:AA,'Log Sales Data'!AB:AB,0,0) -> 1.08 | E20: Tonnes | F20: =SUMIFS('Log Sales Data'!$I:$I,'Log Sales Data'!$C:$C,$B$2,'Log Sales Data'!$D:$D,$B20,'Log Sales Data'!$G:$G,$A20) -> 430 | G20: =IFERROR(H20/F20,"0") -> 195 | H20: =SUM(J20:U20) -> 83850 | J20: =SUMIFS('Log Sales Data'!$M:$M,'Log Sales Data'!$B:$B,J$19,'Log Sales Data'!$C:$C,$B$2,'Log Sales Data'!$D:$D,$B20,'Log Sales Data'!$G:$G,$A20) -> 83850 | K20: =SUMIFS('Log Sales Data'!$M:$M,'Log Sales Data'!$B:$B,K$19,'Log Sales Data'!$C:$C,$B$2,'Log Sales Data'!$D:$D,$B20,'Log Sales Data'!$G:$G,$A20) -> 0 | L20: =SUMIFS('Log Sales Data'!$M:$M,'Log Sales Data'!$B:$B,L$19,'Log Sales Data'!$C:$C,$B$2,'Log Sales Data'!$D:$D,$B20,'Log Sales Data'!$G:$G,$A20) -> 0 | M20: =SUMIFS('Log Sales Data'!$M:$M,'Log Sales Data'!$B:$B,M$19,'Log Sales Data'!$C:$C,$B$2,'Log Sales Data'!$D:$D,$B20,'Log Sales Data'!$G:$G,$A20) -> 0 | N20: =SUMIFS('Log Sales Data'!$M:$M,'Log Sales Data'!$B:$B,N$19,'Log Sales Data'!$C:$C,$B$2,'Log Sales Data'!$D:$D,$B20,'Log Sales Data'!$G:$G,$A20) -> 0 | O20: =SUMIFS('Log Sales Data'!$M:$M,'Log Sales Data'!$B:$B,O$19,'Log Sales Data'!$C:$C,$B$2,'Log Sales Data'!$D:$D,$B20,'Log Sales Data'!$G:$G,$A20) -> 0 | P20: =SUMIFS('Log Sales Data'!$M:$M,'Log Sales Data'!$B:$B,P$19,'Log Sales Data'!$C:$C,$B$2,'Log Sales Data'!$D:$D,$B20,'Log Sales Data'!$G:$G,$A20) -> 0 | Q20: =SUMIFS('Log Sales Data'!$M:$M,'Log Sales Data'!$B:$B,Q$19,'Log Sales Data'!$C:$C,$B$2,'Log Sales Data'!$D:$D,$B20,'Log Sales Data'!$G:$G,$A20) -> 0 | ... U20: =SUMIFS('Log Sales Data'!$M:$M,'Log Sales Data'!$B:$B,U$19,'Log Sales Data'!$C:$C,$B$2,'Log Sales Data'!$D:$D,$B20,'Log Sales Data'!$G:$G,$A20) -> 0
A21: Domestic | B21: S30 | C21: =IFERROR(F21/$F$46,0) -> 0.16468254 | D21: =_xlfn.XLOOKUP(B21,'Log Sales Data'!AA:AA,'Log Sales Data'!AB:AB,0,0) -> 1.03 | E21: Tonnes | F21: =SUMIFS('Log Sales Data'!$I:$I,'Log Sales Data'!$C:$C,$B$2,'Log Sales Data'!$D:$D,$B21,'Log Sales Data'!$G:$G,$A21) -> 830 | G21: =IFERROR(H21/F21,"0") -> 127 | H21: =SUM(J21:U21) -> 105410 | J21: =SUMIFS('Log Sales Data'!$M:$M,'Log Sales Data'!$B:$B,J$19,'Log Sales Data'!$C:$C,$B$2,'Log Sales Data'!$D:$D,$B21,'Log Sales Data'!$G:$G,$A21) -> 105410 | K21: =SUMIFS('Log Sales Data'!$M:$M,'Log Sales Data'!$B:$B,K$19,'Log Sales Data'!$C:$C,$B$2,'Log Sales Data'!$D:$D,$B21,'Log Sales Data'!$G:$G,$A21) -> 0 | L21: =SUMIFS('Log Sales Data'!$M:$M,'Log Sales Data'!$B:$B,L$19,'Log Sales Data'!$C:$C,$B$2,'Log Sales Data'!$D:$D,$B21,'Log Sales Data'!$G:$G,$A21) -> 0 | M21: =SUMIFS('Log Sales Data'!$M:$M,'Log Sales Data'!$B:$B,M$19,'Log Sales Data'!$C:$C,$B$2,'Log Sales Data'!$D:$D,$B21,'Log Sales Data'!$G:$G,$A21) -> 0 | N21: =SUMIFS('Log Sales Data'!$M:$M,'Log Sales Data'!$B:$B,N$19,'Log Sales Data'!$C:$C,$B$2,'Log Sales Data'!$D:$D,$B21,'Log Sales Data'!$G:$G,$A21) -> 0 | O21: =SUMIFS('Log Sales Data'!$M:$M,'Log Sales Data'!$B:$B,O$19,'Log Sales Data'!$C:$C,$B$2,'Log Sales Data'!$D:$D,$B21,'Log Sales Data'!$G:$G,$A21) -> 0 | P21: =SUMIFS('Log Sales Data'!$M:$M,'Log Sales Data'!$B:$B,P$19,'Log Sales Data'!$C:$C,$B$2,'Log Sales Data'!$D:$D,$B21,'Log Sales Data'!$G:$G,$A21) -> 0 | Q21: =SUMIFS('Log Sales Data'!$M:$M,'Log Sales Data'!$B:$B,Q$19,'Log Sales Data'!$C:$C,$B$2,'Log Sales Data'!$D:$D,$B21,'Log Sales Data'!$G:$G,$A21) -> 0 | ... U21: =SUMIFS('Log Sales Data'!$M:$M,'Log Sales Data'!$B:$B,U$19,'Log Sales Data'!$C:$C,$B$2,'Log Sales Data'!$D:$D,$B21,'Log Sales Data'!$G:$G,$A21) -> 0
A22: Domestic | B22: S20 | C22: =IFERROR(F22/$F$46,0) -> 0.24404762 | D22: =_xlfn.XLOOKUP(B22,'Log Sales Data'!AA:AA,'Log Sales Data'!AB:AB,0,0) -> 0.99 | E22: Tonnes | F22: =SUMIFS('Log Sales Data'!$I:$I,'Log Sales Data'!$C:$C,$B$2,'Log Sales Data'!$D:$D,$B22,'Log Sales Data'!$G:$G,$A22) -> 1230 | G22: =IFERROR(H22/F22,"0") -> 120 | H22: =SUM(J22:U22) -> 147600 | J22: =SUMIFS('Log Sales Data'!$M:$M,'Log Sales Data'!$B:$B,J$19,'Log Sales Data'!$C:$C,$B$2,'Log Sales Data'!$D:$D,$B22,'Log Sales Data'!$G:$G,$A22) -> 147600 | K22: =SUMIFS('Log Sales Data'!$M:$M,'Log Sales Data'!$B:$B,K$19,'Log Sales Data'!$C:$C,$B$2,'Log Sales Data'!$D:$D,$B22,'Log Sales Data'!$G:$G,$A22) -> 0 | L22: =SUMIFS('Log Sales Data'!$M:$M,'Log Sales Data'!$B:$B,L$19,'Log Sales Data'!$C:$C,$B$2,'Log Sales Data'!$D:$D,$B22,'Log Sales Data'!$G:$G,$A22) -> 0 | M22: =SUMIFS('Log Sales Data'!$M:$M,'Log Sales Data'!$B:$B,M$19,'Log Sales Data'!$C:$C,$B$2,'Log Sales Data'!$D:$D,$B22,'Log Sales Data'!$G:$G,$A22) -> 0 | N22: =SUMIFS('Log Sales Data'!$M:$M,'Log Sales Data'!$B:$B,N$19,'Log Sales Data'!$C:$C,$B$2,'Log Sales Data'!$D:$D,$B22,'Log Sales Data'!$G:$G,$A22) -> 0 | O22: =SUMIFS('Log Sales Data'!$M:$M,'Log Sales Data'!$B:$B,O$19,'Log Sales Data'!$C:$C,$B$2,'Log Sales Data'!$D:$D,$B22,'Log Sales Data'!$G:$G,$A22) -> 0 | P22: =SUMIFS('Log Sales Data'!$M:$M,'Log Sales Data'!$B:$B,P$19,'Log Sales Data'!$C:$C,$B$2,'Log Sales Data'!$D:$D,$B22,'Log Sales Data'!$G:$G,$A22) -> 0 | Q22: =SUMIFS('Log Sales Data'!$M:$M,'Log Sales Data'!$B:$B,Q$19,'Log Sales Data'!$C:$C,$B$2,'Log Sales Data'!$D:$D,$B22,'Log Sales Data'!$G:$G,$A22) -> 0 | ... U22: =SUMIFS('Log Sales Data'!$M:$M,'Log Sales Data'!$B:$B,U$19,'Log Sales Data'!$C:$C,$B$2,'Log Sales Data'!$D:$D,$B22,'Log Sales Data'!$G:$G,$A22) -> 0
A23: Domestic | B23: Domestic Pulp | C23: =IFERROR(F23/$F$46,0) -> 0 | D23: =_xlfn.XLOOKUP(B23,'Log Sales Data'!AA:AA,'Log Sales Data'!AB:AB,0,0) -> 0.88 | E23: Tonnes | F23: =SUMIFS('Log Sales Data'!$I:$I,'Log Sales Data'!$C:$C,$B$2,'Log Sales Data'!$D:$D,$B23,'Log Sales Data'!$G:$G,$A23) -> 0 | G23: =IFERROR(H23/F23,"0") -> 0 | H23: =SUM(J23:U23) -> 0 | J23: =SUMIFS('Log Sales Data'!$M:$M,'Log Sales Data'!$B:$B,J$19,'Log Sales Data'!$C:$C,$B$2,'Log Sales Data'!$D:$D,$B23,'Log Sales Data'!$G:$G,$A23) -> 0 | K23: =SUMIFS('Log Sales Data'!$M:$M,'Log Sales Data'!$B:$B,K$19,'Log Sales Data'!$C:$C,$B$2,'Log Sales Data'!$D:$D,$B23,'Log Sales Data'!$G:$G,$A23) -> 0 | L23: =SUMIFS('Log Sales Data'!$M:$M,'Log Sales Data'!$B:$B,L$19,'Log Sales Data'!$C:$C,$B$2,'Log Sales Data'!$D:$D,$B23,'Log Sales Data'!$G:$G,$A23) -> 0 | M23: =SUMIFS('Log Sales Data'!$M:$M,'Log Sales Data'!$B:$B,M$19,'Log Sales Data'!$C:$C,$B$2,'Log Sales Data'!$D:$D,$B23,'Log Sales Data'!$G:$G,$A23) -> 0 | N23: =SUMIFS('Log Sales Data'!$M:$M,'Log Sales Data'!$B:$B,N$19,'Log Sales Data'!$C:$C,$B$2,'Log Sales Data'!$D:$D,$B23,'Log Sales Data'!$G:$G,$A23) -> 0 | O23: =SUMIFS('Log Sales Data'!$M:$M,'Log Sales Data'!$B:$B,O$19,'Log Sales Data'!$C:$C,$B$2,'Log Sales Data'!$D:$D,$B23,'Log Sales Data'!$G:$G,$A23) -> 0 | P23: =SUMIFS('Log Sales Data'!$M:$M,'Log Sales Data'!$B:$B,P$19,'Log Sales Data'!$C:$C,$B$2,'Log Sales Data'!$D:$D,$B23,'Log Sales Data'!$G:$G,$A23) -> 0 | Q23: =SUMIFS('Log Sales Data'!$M:$M,'Log Sales Data'!$B:$B,Q$19,'Log Sales Data'!$C:$C,$B$2,'Log Sales Data'!$D:$D,$B23,'Log Sales Data'!$G:$G,$A23) -> 0 | ... U23: =SUMIFS('Log Sales Data'!$M:$M,'Log Sales Data'!$B:$B,U$19,'Log Sales Data'!$C:$C,$B$2,'Log Sales Data'!$D:$D,$B23,'Log Sales Data'!$G:$G,$A23) -> 0
A24: Domestic | B24: Eucalyptus | C24: =IFERROR(F24/$F$46,0) -> 0 | D24: =_xlfn.XLOOKUP(B24,'Log Sales Data'!AA:AA,'Log Sales Data'!AB:AB,0,0) -> 0.95 | E24: Tonnes | F24: =SUMIFS('Log Sales Data'!$I:$I,'Log Sales Data'!$C:$C,$B$2,'Log Sales Data'!$D:$D,$B24,'Log Sales Data'!$G:$G,$A24) -> 0 | G24: =IFERROR(H24/F24,"0") -> 0 | H24: =SUM(J24:U24) -> 0 | J24: =SUMIFS('Log Sales Data'!$M:$M,'Log Sales Data'!$B:$B,J$19,'Log Sales Data'!$C:$C,$B$2,'Log Sales Data'!$D:$D,$B24,'Log Sales Data'!$G:$G,$A24) -> 0 | K24: =SUMIFS('Log Sales Data'!$M:$M,'Log Sales Data'!$B:$B,K$19,'Log Sales Data'!$C:$C,$B$2,'Log Sales Data'!$D:$D,$B24,'Log Sales Data'!$G:$G,$A24) -> 0 | L24: =SUMIFS('Log Sales Data'!$M:$M,'Log Sales Data'!$B:$B,L$19,'Log Sales Data'!$C:$C,$B$2,'Log Sales Data'!$D:$D,$B24,'Log Sales Data'!$G:$G,$A24) -> 0 | M24: =SUMIFS('Log Sales Data'!$M:$M,'Log Sales Data'!$B:$B,M$19,'Log Sales Data'!$C:$C,$B$2,'Log Sales Data'!$D:$D,$B24,'Log Sales Data'!$G:$G,$A24) -> 0 | N24: =SUMIFS('Log Sales Data'!$M:$M,'Log Sales Data'!$B:$B,N$19,'Log Sales Data'!$C:$C,$B$2,'Log Sales Data'!$D:$D,$B24,'Log Sales Data'!$G:$G,$A24) -> 0 | O24: =SUMIFS('Log Sales Data'!$M:$M,'Log Sales Data'!$B:$B,O$19,'Log Sales Data'!$C:$C,$B$2,'Log Sales Data'!$D:$D,$B24,'Log Sales Data'!$G:$G,$A24) -> 0 | P24: =SUMIFS('Log Sales Data'!$M:$M,'Log Sales Data'!$B:$B,P$19,'Log Sales Data'!$C:$C,$B$2,'Log Sales Data'!$D:$D,$B24,'Log Sales Data'!$G:$G,$A24) -> 0 | Q24: =SUMIFS('Log Sales Data'!$M:$M,'Log Sales Data'!$B:$B,Q$19,'Log Sales Data'!$C:$C,$B$2,'Log Sales Data'!$D:$D,$B24,'Log Sales Data'!$G:$G,$A24) -> 0 | ... U24: =SUMIFS('Log Sales Data'!$M:$M,'Log Sales Data'!$B:$B,U$19,'Log Sales Data'!$C:$C,$B$2,'Log Sales Data'!$D:$D,$B24,'Log Sales Data'!$G:$G,$A24) -> 0
A25: Domestic | B25: FW | C25: =IFERROR(F25/$F$46,0) -> 0 | D25: =_xlfn.XLOOKUP(B25,'Log Sales Data'!AA:AA,'Log Sales Data'!AB:AB,0,0) -> 0.95 | E25: Tonnes | F25: =SUMIFS('Log Sales Data'!$I:$I,'Log Sales Data'!$C:$C,$B$2,'Log Sales Data'!$D:$D,$B25,'Log Sales Data'!$G:$G,$A25) -> 0 | G25: =IFERROR(H25/F25,"0") -> 0 | H25: =SUM(J25:U25) -> 0 | J25: =SUMIFS('Log Sales Data'!$M:$M,'Log Sales Data'!$B:$B,J$19,'Log Sales Data'!$C:$C,$B$2,'Log Sales Data'!$D:$D,$B25,'Log Sales Data'!$G:$G,$A25) -> 0 | K25: =SUMIFS('Log Sales Data'!$M:$M,'Log Sales Data'!$B:$B,K$19,'Log Sales Data'!$C:$C,$B$2,'Log Sales Data'!$D:$D,$B25,'Log Sales Data'!$G:$G,$A25) -> 0 | L25: =SUMIFS('Log Sales Data'!$M:$M,'Log Sales Data'!$B:$B,L$19,'Log Sales Data'!$C:$C,$B$2,'Log Sales Data'!$D:$D,$B25,'Log Sales Data'!$G:$G,$A25) -> 0 | M25: =SUMIFS('Log Sales Data'!$M:$M,'Log Sales Data'!$B:$B,M$19,'Log Sales Data'!$C:$C,$B$2,'Log Sales Data'!$D:$D,$B25,'Log Sales Data'!$G:$G,$A25) -> 0 | N25: =SUMIFS('Log Sales Data'!$M:$M,'Log Sales Data'!$B:$B,N$19,'Log Sales Data'!$C:$C,$B$2,'Log Sales Data'!$D:$D,$B25,'Log Sales Data'!$G:$G,$A25) -> 0 | O25: =SUMIFS('Log Sales Data'!$M:$M,'Log Sales Data'!$B:$B,O$19,'Log Sales Data'!$C:$C,$B$2,'Log Sales Data'!$D:$D,$B25,'Log Sales Data'!$G:$G,$A25) -> 0 | P25: =SUMIFS('Log Sales Data'!$M:$M,'Log Sales Data'!$B:$B,P$19,'Log Sales Data'!$C:$C,$B$2,'Log Sales Data'!$D:$D,$B25,'Log Sales Data'!$G:$G,$A25) -> 0 | Q25: =SUMIFS('Log Sales Data'!$M:$M,'Log Sales Data'!$B:$B,Q$19,'Log Sales Data'!$C:$C,$B$2,'Log Sales Data'!$D:$D,$B25,'Log Sales Data'!$G:$G,$A25) -> 0 | ... U25: =SUMIFS('Log Sales Data'!$M:$M,'Log Sales Data'!$B:$B,U$19,'Log Sales Data'!$C:$C,$B$2,'Log Sales Data'!$D:$D,$B25,'Log Sales Data'!$G:$G,$A25) -> 0
A26: Domestic | B26: Euc Pulp | C26: =IFERROR(F26/$F$46,0) -> 0 | D26: =_xlfn.XLOOKUP(B26,'Log Sales Data'!AA:AA,'Log Sales Data'!AB:AB,0,0) -> 0.88 | E26: Tonnes | F26: =SUMIFS('Log Sales Data'!$I:$I,'Log Sales Data'!$C:$C,$B$2,'Log Sales Data'!$D:$D,$B26,'Log Sales Data'!$G:$G,$A26) -> 0 | G26: =IFERROR(H26/F26,"0") -> 0 | H26: =SUM(J26:U26) -> 0 | J26: =SUMIFS('Log Sales Data'!$M:$M,'Log Sales Data'!$B:$B,J$19,'Log Sales Data'!$C:$C,$B$2,'Log Sales Data'!$D:$D,$B26,'Log Sales Data'!$G:$G,$A26) -> 0 | K26: =SUMIFS('Log Sales Data'!$M:$M,'Log Sales Data'!$B:$B,K$19,'Log Sales Data'!$C:$C,$B$2,'Log Sales Data'!$D:$D,$B26,'Log Sales Data'!$G:$G,$A26) -> 0 | L26: =SUMIFS('Log Sales Data'!$M:$M,'Log Sales Data'!$B:$B,L$19,'Log Sales Data'!$C:$C,$B$2,'Log Sales Data'!$D:$D,$B26,'Log Sales Data'!$G:$G,$A26) -> 0 | M26: =SUMIFS('Log Sales Data'!$M:$M,'Log Sales Data'!$B:$B,M$19,'Log Sales Data'!$C:$C,$B$2,'Log Sales Data'!$D:$D,$B26,'Log Sales Data'!$G:$G,$A26) -> 0 | N26: =SUMIFS('Log Sales Data'!$M:$M,'Log Sales Data'!$B:$B,N$19,'Log Sales Data'!$C:$C,$B$2,'Log Sales Data'!$D:$D,$B26,'Log Sales Data'!$G:$G,$A26) -> 0 | O26: =SUMIFS('Log Sales Data'!$M:$M,'Log Sales Data'!$B:$B,O$19,'Log Sales Data'!$C:$C,$B$2,'Log Sales Data'!$D:$D,$B26,'Log Sales Data'!$G:$G,$A26) -> 0 | P26: =SUMIFS('Log Sales Data'!$M:$M,'Log Sales Data'!$B:$B,P$19,'Log Sales Data'!$C:$C,$B$2,'Log Sales Data'!$D:$D,$B26,'Log Sales Data'!$G:$G,$A26) -> 0 | Q26: =SUMIFS('Log Sales Data'!$M:$M,'Log Sales Data'!$B:$B,Q$19,'Log Sales Data'!$C:$C,$B$2,'Log Sales Data'!$D:$D,$B26,'Log Sales Data'!$G:$G,$A26) -> 0 | ... U26: =SUMIFS('Log Sales Data'!$M:$M,'Log Sales Data'!$B:$B,U$19,'Log Sales Data'!$C:$C,$B$2,'Log Sales Data'!$D:$D,$B26,'Log Sales Data'!$G:$G,$A26) -> 0
A27: Domestic | B27: Binwood | C27: =IFERROR(F27/$F$46,0) -> 0 | D27: =_xlfn.XLOOKUP(B27,'Log Sales Data'!AA:AA,'Log Sales Data'!AB:AB,0,0) -> 0.88 | E27: Tonnes | F27: =SUMIFS('Log Sales Data'!$I:$I,'Log Sales Data'!$C:$C,$B$2,'Log Sales Data'!$D:$D,$B27,'Log Sales Data'!$G:$G,$A27) -> 0 | G27: =IFERROR(H27/F27,"0") -> 0 | H27: =SUM(J27:U27) -> 0 | J27: =SUMIFS('Log Sales Data'!$M:$M,'Log Sales Data'!$B:$B,J$19,'Log Sales Data'!$C:$C,$B$2,'Log Sales Data'!$D:$D,$B27,'Log Sales Data'!$G:$G,$A27) -> 0 | K27: =SUMIFS('Log Sales Data'!$M:$M,'Log Sales Data'!$B:$B,K$19,'Log Sales Data'!$C:$C,$B$2,'Log Sales Data'!$D:$D,$B27,'Log Sales Data'!$G:$G,$A27) -> 0 | L27: =SUMIFS('Log Sales Data'!$M:$M,'Log Sales Data'!$B:$B,L$19,'Log Sales Data'!$C:$C,$B$2,'Log Sales Data'!$D:$D,$B27,'Log Sales Data'!$G:$G,$A27) -> 0 | M27: =SUMIFS('Log Sales Data'!$M:$M,'Log Sales Data'!$B:$B,M$19,'Log Sales Data'!$C:$C,$B$2,'Log Sales Data'!$D:$D,$B27,'Log Sales Data'!$G:$G,$A27) -> 0 | N27: =SUMIFS('Log Sales Data'!$M:$M,'Log Sales Data'!$B:$B,N$19,'Log Sales Data'!$C:$C,$B$2,'Log Sales Data'!$D:$D,$B27,'Log Sales Data'!$G:$G,$A27) -> 0 | O27: =SUMIFS('Log Sales Data'!$M:$M,'Log Sales Data'!$B:$B,O$19,'Log Sales Data'!$C:$C,$B$2,'Log Sales Data'!$D:$D,$B27,'Log Sales Data'!$G:$G,$A27) -> 0 | P27: =SUMIFS('Log Sales Data'!$M:$M,'Log Sales Data'!$B:$B,P$19,'Log Sales Data'!$C:$C,$B$2,'Log Sales Data'!$D:$D,$B27,'Log Sales Data'!$G:$G,$A27) -> 0 | Q27: =SUMIFS('Log Sales Data'!$M:$M,'Log Sales Data'!$B:$B,Q$19,'Log Sales Data'!$C:$C,$B$2,'Log Sales Data'!$D:$D,$B27,'Log Sales Data'!$G:$G,$A27) -> 0 | ... U27: =SUMIFS('Log Sales Data'!$M:$M,'Log Sales Data'!$B:$B,U$19,'Log Sales Data'!$C:$C,$B$2,'Log Sales Data'!$D:$D,$B27,'Log Sales Data'!$G:$G,$A27) -> 0
A28: Domestic | B28: Spare Grade | E28: Tonnes | H28: =SUM(J28:U28) -> 0 | J28: =SUMIFS('Log Sales Data'!$M:$M,'Log Sales Data'!$B:$B,J$19,'Log Sales Data'!$C:$C,$B$2,'Log Sales Data'!$D:$D,$B28,'Log Sales Data'!$G:$G,$A28) -> 0 | K28: =SUMIFS('Log Sales Data'!$M:$M,'Log Sales Data'!$B:$B,K$19,'Log Sales Data'!$C:$C,$B$2,'Log Sales Data'!$D:$D,$B28,'Log Sales Data'!$G:$G,$A28) -> 0 | L28: =SUMIFS('Log Sales Data'!$M:$M,'Log Sales Data'!$B:$B,L$19,'Log Sales Data'!$C:$C,$B$2,'Log Sales Data'!$D:$D,$B28,'Log Sales Data'!$G:$G,$A28) -> 0 | M28: =SUMIFS('Log Sales Data'!$M:$M,'Log Sales Data'!$B:$B,M$19,'Log Sales Data'!$C:$C,$B$2,'Log Sales Data'!$D:$D,$B28,'Log Sales Data'!$G:$G,$A28) -> 0 | N28: =SUMIFS('Log Sales Data'!$M:$M,'Log Sales Data'!$B:$B,N$19,'Log Sales Data'!$C:$C,$B$2,'Log Sales Data'!$D:$D,$B28,'Log Sales Data'!$G:$G,$A28) -> 0 | O28: =SUMIFS('Log Sales Data'!$M:$M,'Log Sales Data'!$B:$B,O$19,'Log Sales Data'!$C:$C,$B$2,'Log Sales Data'!$D:$D,$B28,'Log Sales Data'!$G:$G,$A28) -> 0 | P28: =SUMIFS('Log Sales Data'!$M:$M,'Log Sales Data'!$B:$B,P$19,'Log Sales Data'!$C:$C,$B$2,'Log Sales Data'!$D:$D,$B28,'Log Sales Data'!$G:$G,$A28) -> 0 | Q28: =SUMIFS('Log Sales Data'!$M:$M,'Log Sales Data'!$B:$B,Q$19,'Log Sales Data'!$C:$C,$B$2,'Log Sales Data'!$D:$D,$B28,'Log Sales Data'!$G:$G,$A28) -> 0 | ... U28: =SUMIFS('Log Sales Data'!$M:$M,'Log Sales Data'!$B:$B,U$19,'Log Sales Data'!$C:$C,$B$2,'Log Sales Data'!$D:$D,$B28,'Log Sales Data'!$G:$G,$A28) -> 0
A29: Export | B29: P40 | C29: =IFERROR(F29/$F$46,0) -> 0.089285714 | D29: =_xlfn.XLOOKUP(B29,'Log Sales Data'!AA:AA,'Log Sales Data'!AB:AB,0,0) -> 1.09 | E29: Tonnes | F29: =SUMIFS('Log Sales Data'!$I:$I,'Log Sales Data'!$C:$C,$B$2,'Log Sales Data'!$D:$D,$B29,'Log Sales Data'!$G:$G,$A29) -> 450 | G29: =IFERROR(H29/F29,"0") -> 195 | H29: =SUM(J29:U29) -> 87750 | J29: =SUMIFS('Log Sales Data'!$M:$M,'Log Sales Data'!$B:$B,J$19,'Log Sales Data'!$C:$C,$B$2,'Log Sales Data'!$D:$D,$B29,'Log Sales Data'!$G:$G,$A29) -> 87750 | K29: =SUMIFS('Log Sales Data'!$M:$M,'Log Sales Data'!$B:$B,K$19,'Log Sales Data'!$C:$C,$B$2,'Log Sales Data'!$D:$D,$B29,'Log Sales Data'!$G:$G,$A29) -> 0 | L29: =SUMIFS('Log Sales Data'!$M:$M,'Log Sales Data'!$B:$B,L$19,'Log Sales Data'!$C:$C,$B$2,'Log Sales Data'!$D:$D,$B29,'Log Sales Data'!$G:$G,$A29) -> 0 | M29: =SUMIFS('Log Sales Data'!$M:$M,'Log Sales Data'!$B:$B,M$19,'Log Sales Data'!$C:$C,$B$2,'Log Sales Data'!$D:$D,$B29,'Log Sales Data'!$G:$G,$A29) -> 0 | N29: =SUMIFS('Log Sales Data'!$M:$M,'Log Sales Data'!$B:$B,N$19,'Log Sales Data'!$C:$C,$B$2,'Log Sales Data'!$D:$D,$B29,'Log Sales Data'!$G:$G,$A29) -> 0 | O29: =SUMIFS('Log Sales Data'!$M:$M,'Log Sales Data'!$B:$B,O$19,'Log Sales Data'!$C:$C,$B$2,'Log Sales Data'!$D:$D,$B29,'Log Sales Data'!$G:$G,$A29) -> 0 | P29: =SUMIFS('Log Sales Data'!$M:$M,'Log Sales Data'!$B:$B,P$19,'Log Sales Data'!$C:$C,$B$2,'Log Sales Data'!$D:$D,$B29,'Log Sales Data'!$G:$G,$A29) -> 0 | Q29: =SUMIFS('Log Sales Data'!$M:$M,'Log Sales Data'!$B:$B,Q$19,'Log Sales Data'!$C:$C,$B$2,'Log Sales Data'!$D:$D,$B29,'Log Sales Data'!$G:$G,$A29) -> 0 | ... U29: =SUMIFS('Log Sales Data'!$M:$M,'Log Sales Data'!$B:$B,U$19,'Log Sales Data'!$C:$C,$B$2,'Log Sales Data'!$D:$D,$B29,'Log Sales Data'!$G:$G,$A29) -> 0
A30: Export | B30: P30 | C30: =IFERROR(F30/$F$46,0) -> 0 | D30: =_xlfn.XLOOKUP(B30,'Log Sales Data'!AA:AA,'Log Sales Data'!AB:AB,0,0) -> 1.07 | E30: Tonnes | F30: =SUMIFS('Log Sales Data'!$I:$I,'Log Sales Data'!$C:$C,$B$2,'Log Sales Data'!$D:$D,$B30,'Log Sales Data'!$G:$G,$A30) -> 0 | G30: =IFERROR(H30/F30,"0") -> 0 | H30: =SUM(J30:U30) -> 0 | J30: =SUMIFS('Log Sales Data'!$M:$M,'Log Sales Data'!$B:$B,J$19,'Log Sales Data'!$C:$C,$B$2,'Log Sales Data'!$D:$D,$B30,'Log Sales Data'!$G:$G,$A30) -> 0 | K30: =SUMIFS('Log Sales Data'!$M:$M,'Log Sales Data'!$B:$B,K$19,'Log Sales Data'!$C:$C,$B$2,'Log Sales Data'!$D:$D,$B30,'Log Sales Data'!$G:$G,$A30) -> 0 | L30: =SUMIFS('Log Sales Data'!$M:$M,'Log Sales Data'!$B:$B,L$19,'Log Sales Data'!$C:$C,$B$2,'Log Sales Data'!$D:$D,$B30,'Log Sales Data'!$G:$G,$A30) -> 0 | M30: =SUMIFS('Log Sales Data'!$M:$M,'Log Sales Data'!$B:$B,M$19,'Log Sales Data'!$C:$C,$B$2,'Log Sales Data'!$D:$D,$B30,'Log Sales Data'!$G:$G,$A30) -> 0 | N30: =SUMIFS('Log Sales Data'!$M:$M,'Log Sales Data'!$B:$B,N$19,'Log Sales Data'!$C:$C,$B$2,'Log Sales Data'!$D:$D,$B30,'Log Sales Data'!$G:$G,$A30) -> 0 | O30: =SUMIFS('Log Sales Data'!$M:$M,'Log Sales Data'!$B:$B,O$19,'Log Sales Data'!$C:$C,$B$2,'Log Sales Data'!$D:$D,$B30,'Log Sales Data'!$G:$G,$A30) -> 0 | P30: =SUMIFS('Log Sales Data'!$M:$M,'Log Sales Data'!$B:$B,P$19,'Log Sales Data'!$C:$C,$B$2,'Log Sales Data'!$D:$D,$B30,'Log Sales Data'!$G:$G,$A30) -> 0 | Q30: =SUMIFS('Log Sales Data'!$M:$M,'Log Sales Data'!$B:$B,Q$19,'Log Sales Data'!$C:$C,$B$2,'Log Sales Data'!$D:$D,$B30,'Log Sales Data'!$G:$G,$A30) -> 0 | ... U30: =SUMIFS('Log Sales Data'!$M:$M,'Log Sales Data'!$B:$B,U$19,'Log Sales Data'!$C:$C,$B$2,'Log Sales Data'!$D:$D,$B30,'Log Sales Data'!$G:$G,$A30) -> 0
A31: Export | B31: AO | C31: =IFERROR(F31/$F$46,0) -> 0 | D31: =_xlfn.XLOOKUP(B31,'Log Sales Data'!AA:AA,'Log Sales Data'!AB:AB,0,0) -> 1.03 | E31: Tonnes | F31: =SUMIFS('Log Sales Data'!$I:$I,'Log Sales Data'!$C:$C,$B$2,'Log Sales Data'!$D:$D,$B31,'Log Sales Data'!$G:$G,$A31) -> 0 | G31: =IFERROR(H31/F31,"0") -> 0 | H31: =SUM(J31:U31) -> 0 | J31: =SUMIFS('Log Sales Data'!$M:$M,'Log Sales Data'!$B:$B,J$19,'Log Sales Data'!$C:$C,$B$2,'Log Sales Data'!$D:$D,$B31,'Log Sales Data'!$G:$G,$A31) -> 0 | K31: =SUMIFS('Log Sales Data'!$M:$M,'Log Sales Data'!$B:$B,K$19,'Log Sales Data'!$C:$C,$B$2,'Log Sales Data'!$D:$D,$B31,'Log Sales Data'!$G:$G,$A31) -> 0 | L31: =SUMIFS('Log Sales Data'!$M:$M,'Log Sales Data'!$B:$B,L$19,'Log Sales Data'!$C:$C,$B$2,'Log Sales Data'!$D:$D,$B31,'Log Sales Data'!$G:$G,$A31) -> 0 | M31: =SUMIFS('Log Sales Data'!$M:$M,'Log Sales Data'!$B:$B,M$19,'Log Sales Data'!$C:$C,$B$2,'Log Sales Data'!$D:$D,$B31,'Log Sales Data'!$G:$G,$A31) -> 0 | N31: =SUMIFS('Log Sales Data'!$M:$M,'Log Sales Data'!$B:$B,N$19,'Log Sales Data'!$C:$C,$B$2,'Log Sales Data'!$D:$D,$B31,'Log Sales Data'!$G:$G,$A31) -> 0 | O31: =SUMIFS('Log Sales Data'!$M:$M,'Log Sales Data'!$B:$B,O$19,'Log Sales Data'!$C:$C,$B$2,'Log Sales Data'!$D:$D,$B31,'Log Sales Data'!$G:$G,$A31) -> 0 | P31: =SUMIFS('Log Sales Data'!$M:$M,'Log Sales Data'!$B:$B,P$19,'Log Sales Data'!$C:$C,$B$2,'Log Sales Data'!$D:$D,$B31,'Log Sales Data'!$G:$G,$A31) -> 0 | Q31: =SUMIFS('Log Sales Data'!$M:$M,'Log Sales Data'!$B:$B,Q$19,'Log Sales Data'!$C:$C,$B$2,'Log Sales Data'!$D:$D,$B31,'Log Sales Data'!$G:$G,$A31) -> 0 | ... U31: =SUMIFS('Log Sales Data'!$M:$M,'Log Sales Data'!$B:$B,U$19,'Log Sales Data'!$C:$C,$B$2,'Log Sales Data'!$D:$D,$B31,'Log Sales Data'!$G:$G,$A31) -> 0
A32: Export | B32: A | C32: =IFERROR(F32/$F$46,0) -> 0.16865079 | D32: =_xlfn.XLOOKUP(B32,'Log Sales Data'!AA:AA,'Log Sales Data'!AB:AB,0,0) -> 1.03 | E32: Tonnes | F32: =SUMIFS('Log Sales Data'!$I:$I,'Log Sales Data'!$C:$C,$B$2,'Log Sales Data'!$D:$D,$B32,'Log Sales Data'!$G:$G,$A32) -> 850 | G32: =IFERROR(H32/F32,"0") -> 127 | H32: =SUM(J32:U32) -> 107950 | J32: =SUMIFS('Log Sales Data'!$M:$M,'Log Sales Data'!$B:$B,J$19,'Log Sales Data'!$C:$C,$B$2,'Log Sales Data'!$D:$D,$B32,'Log Sales Data'!$G:$G,$A32) -> 107950 | K32: =SUMIFS('Log Sales Data'!$M:$M,'Log Sales Data'!$B:$B,K$19,'Log Sales Data'!$C:$C,$B$2,'Log Sales Data'!$D:$D,$B32,'Log Sales Data'!$G:$G,$A32) -> 0 | L32: =SUMIFS('Log Sales Data'!$M:$M,'Log Sales Data'!$B:$B,L$19,'Log Sales Data'!$C:$C,$B$2,'Log Sales Data'!$D:$D,$B32,'Log Sales Data'!$G:$G,$A32) -> 0 | M32: =SUMIFS('Log Sales Data'!$M:$M,'Log Sales Data'!$B:$B,M$19,'Log Sales Data'!$C:$C,$B$2,'Log Sales Data'!$D:$D,$B32,'Log Sales Data'!$G:$G,$A32) -> 0 | N32: =SUMIFS('Log Sales Data'!$M:$M,'Log Sales Data'!$B:$B,N$19,'Log Sales Data'!$C:$C,$B$2,'Log Sales Data'!$D:$D,$B32,'Log Sales Data'!$G:$G,$A32) -> 0 | O32: =SUMIFS('Log Sales Data'!$M:$M,'Log Sales Data'!$B:$B,O$19,'Log Sales Data'!$C:$C,$B$2,'Log Sales Data'!$D:$D,$B32,'Log Sales Data'!$G:$G,$A32) -> 0 | P32: =SUMIFS('Log Sales Data'!$M:$M,'Log Sales Data'!$B:$B,P$19,'Log Sales Data'!$C:$C,$B$2,'Log Sales Data'!$D:$D,$B32,'Log Sales Data'!$G:$G,$A32) -> 0 | Q32: =SUMIFS('Log Sales Data'!$M:$M,'Log Sales Data'!$B:$B,Q$19,'Log Sales Data'!$C:$C,$B$2,'Log Sales Data'!$D:$D,$B32,'Log Sales Data'!$G:$G,$A32) -> 0 | ... U32: =SUMIFS('Log Sales Data'!$M:$M,'Log Sales Data'!$B:$B,U$19,'Log Sales Data'!$C:$C,$B$2,'Log Sales Data'!$D:$D,$B32,'Log Sales Data'!$G:$G,$A32) -> 0
A33: Export | B33: K | C33: =IFERROR(F33/$F$46,0) -> 0.24801587 | D33: =_xlfn.XLOOKUP(B33,'Log Sales Data'!AA:AA,'Log Sales Data'!AB:AB,0,0) -> 0.99 | E33: Tonnes | F33: =SUMIFS('Log Sales Data'!$I:$I,'Log Sales Data'!$C:$C,$B$2,'Log Sales Data'!$D:$D,$B33,'Log Sales Data'!$G:$G,$A33) -> 1250 | G33: =IFERROR(H33/F33,"0") -> 120 | H33: =SUM(J33:U33) -> 150000 | J33: =SUMIFS('Log Sales Data'!$M:$M,'Log Sales Data'!$B:$B,J$19,'Log Sales Data'!$C:$C,$B$2,'Log Sales Data'!$D:$D,$B33,'Log Sales Data'!$G:$G,$A33) -> 150000 | K33: =SUMIFS('Log Sales Data'!$M:$M,'Log Sales Data'!$B:$B,K$19,'Log Sales Data'!$C:$C,$B$2,'Log Sales Data'!$D:$D,$B33,'Log Sales Data'!$G:$G,$A33) -> 0 | L33: =SUMIFS('Log Sales Data'!$M:$M,'Log Sales Data'!$B:$B,L$19,'Log Sales Data'!$C:$C,$B$2,'Log Sales Data'!$D:$D,$B33,'Log Sales Data'!$G:$G,$A33) -> 0 | M33: =SUMIFS('Log Sales Data'!$M:$M,'Log Sales Data'!$B:$B,M$19,'Log Sales Data'!$C:$C,$B$2,'Log Sales Data'!$D:$D,$B33,'Log Sales Data'!$G:$G,$A33) -> 0 | N33: =SUMIFS('Log Sales Data'!$M:$M,'Log Sales Data'!$B:$B,N$19,'Log Sales Data'!$C:$C,$B$2,'Log Sales Data'!$D:$D,$B33,'Log Sales Data'!$G:$G,$A33) -> 0 | O33: =SUMIFS('Log Sales Data'!$M:$M,'Log Sales Data'!$B:$B,O$19,'Log Sales Data'!$C:$C,$B$2,'Log Sales Data'!$D:$D,$B33,'Log Sales Data'!$G:$G,$A33) -> 0 | P33: =SUMIFS('Log Sales Data'!$M:$M,'Log Sales Data'!$B:$B,P$19,'Log Sales Data'!$C:$C,$B$2,'Log Sales Data'!$D:$D,$B33,'Log Sales Data'!$G:$G,$A33) -> 0 | Q33: =SUMIFS('Log Sales Data'!$M:$M,'Log Sales Data'!$B:$B,Q$19,'Log Sales Data'!$C:$C,$B$2,'Log Sales Data'!$D:$D,$B33,'Log Sales Data'!$G:$G,$A33) -> 0 | ... U33: =SUMIFS('Log Sales Data'!$M:$M,'Log Sales Data'!$B:$B,U$19,'Log Sales Data'!$C:$C,$B$2,'Log Sales Data'!$D:$D,$B33,'Log Sales Data'!$G:$G,$A33) -> 0
A34: Export | B34: KI | C34: =IFERROR(F34/$F$46,0) -> 0 | D34: =_xlfn.XLOOKUP(B34,'Log Sales Data'!AA:AA,'Log Sales Data'!AB:AB,0,0) -> 0.97 | E34: Tonnes | F34: =SUMIFS('Log Sales Data'!$I:$I,'Log Sales Data'!$C:$C,$B$2,'Log Sales Data'!$D:$D,$B34,'Log Sales Data'!$G:$G,$A34) -> 0 | G34: =IFERROR(H34/F34,"0") -> 0 | H34: =SUM(J34:U34) -> 0 | J34: =SUMIFS('Log Sales Data'!$M:$M,'Log Sales Data'!$B:$B,J$19,'Log Sales Data'!$C:$C,$B$2,'Log Sales Data'!$D:$D,$B34,'Log Sales Data'!$G:$G,$A34) -> 0 | K34: =SUMIFS('Log Sales Data'!$M:$M,'Log Sales Data'!$B:$B,K$19,'Log Sales Data'!$C:$C,$B$2,'Log Sales Data'!$D:$D,$B34,'Log Sales Data'!$G:$G,$A34) -> 0 | L34: =SUMIFS('Log Sales Data'!$M:$M,'Log Sales Data'!$B:$B,L$19,'Log Sales Data'!$C:$C,$B$2,'Log Sales Data'!$D:$D,$B34,'Log Sales Data'!$G:$G,$A34) -> 0 | M34: =SUMIFS('Log Sales Data'!$M:$M,'Log Sales Data'!$B:$B,M$19,'Log Sales Data'!$C:$C,$B$2,'Log Sales Data'!$D:$D,$B34,'Log Sales Data'!$G:$G,$A34) -> 0 | N34: =SUMIFS('Log Sales Data'!$M:$M,'Log Sales Data'!$B:$B,N$19,'Log Sales Data'!$C:$C,$B$2,'Log Sales Data'!$D:$D,$B34,'Log Sales Data'!$G:$G,$A34) -> 0 | O34: =SUMIFS('Log Sales Data'!$M:$M,'Log Sales Data'!$B:$B,O$19,'Log Sales Data'!$C:$C,$B$2,'Log Sales Data'!$D:$D,$B34,'Log Sales Data'!$G:$G,$A34) -> 0 | P34: =SUMIFS('Log Sales Data'!$M:$M,'Log Sales Data'!$B:$B,P$19,'Log Sales Data'!$C:$C,$B$2,'Log Sales Data'!$D:$D,$B34,'Log Sales Data'!$G:$G,$A34) -> 0 | Q34: =SUMIFS('Log Sales Data'!$M:$M,'Log Sales Data'!$B:$B,Q$19,'Log Sales Data'!$C:$C,$B$2,'Log Sales Data'!$D:$D,$B34,'Log Sales Data'!$G:$G,$A34) -> 0 | ... U34: =SUMIFS('Log Sales Data'!$M:$M,'Log Sales Data'!$B:$B,U$19,'Log Sales Data'!$C:$C,$B$2,'Log Sales Data'!$D:$D,$B34,'Log Sales Data'!$G:$G,$A34) -> 0
A35: Export | B35: KIS | C35: =IFERROR(F35/$F$46,0) -> 0 | D35: =_xlfn.XLOOKUP(B35,'Log Sales Data'!AA:AA,'Log Sales Data'!AB:AB,0,0) -> 0.88 | E35: Tonnes | F35: =SUMIFS('Log Sales Data'!$I:$I,'Log Sales Data'!$C:$C,$B$2,'Log Sales Data'!$D:$D,$B35,'Log Sales Data'!$G:$G,$A35) -> 0 | G35: =IFERROR(H35/F35,"0") -> 0 | H35: =SUM(J35:U35) -> 0 | J35: =SUMIFS('Log Sales Data'!$M:$M,'Log Sales Data'!$B:$B,J$19,'Log Sales Data'!$C:$C,$B$2,'Log Sales Data'!$D:$D,$B35,'Log Sales Data'!$G:$G,$A35) -> 0 | K35: =SUMIFS('Log Sales Data'!$M:$M,'Log Sales Data'!$B:$B,K$19,'Log Sales Data'!$C:$C,$B$2,'Log Sales Data'!$D:$D,$B35,'Log Sales Data'!$G:$G,$A35) -> 0 | L35: =SUMIFS('Log Sales Data'!$M:$M,'Log Sales Data'!$B:$B,L$19,'Log Sales Data'!$C:$C,$B$2,'Log Sales Data'!$D:$D,$B35,'Log Sales Data'!$G:$G,$A35) -> 0 | M35: =SUMIFS('Log Sales Data'!$M:$M,'Log Sales Data'!$B:$B,M$19,'Log Sales Data'!$C:$C,$B$2,'Log Sales Data'!$D:$D,$B35,'Log Sales Data'!$G:$G,$A35) -> 0 | N35: =SUMIFS('Log Sales Data'!$M:$M,'Log Sales Data'!$B:$B,N$19,'Log Sales Data'!$C:$C,$B$2,'Log Sales Data'!$D:$D,$B35,'Log Sales Data'!$G:$G,$A35) -> 0 | O35: =SUMIFS('Log Sales Data'!$M:$M,'Log Sales Data'!$B:$B,O$19,'Log Sales Data'!$C:$C,$B$2,'Log Sales Data'!$D:$D,$B35,'Log Sales Data'!$G:$G,$A35) -> 0 | P35: =SUMIFS('Log Sales Data'!$M:$M,'Log Sales Data'!$B:$B,P$19,'Log Sales Data'!$C:$C,$B$2,'Log Sales Data'!$D:$D,$B35,'Log Sales Data'!$G:$G,$A35) -> 0 | Q35: =SUMIFS('Log Sales Data'!$M:$M,'Log Sales Data'!$B:$B,Q$19,'Log Sales Data'!$C:$C,$B$2,'Log Sales Data'!$D:$D,$B35,'Log Sales Data'!$G:$G,$A35) -> 0 | ... U35: =SUMIFS('Log Sales Data'!$M:$M,'Log Sales Data'!$B:$B,U$19,'Log Sales Data'!$C:$C,$B$2,'Log Sales Data'!$D:$D,$B35,'Log Sales Data'!$G:$G,$A35) -> 0
A36: Export | B36: KI stub | C36: =IFERROR(F36/$F$46,0) -> 0 | D36: =_xlfn.XLOOKUP(B36,'Log Sales Data'!AA:AA,'Log Sales Data'!AB:AB,0,0) -> 0.97 | E36: Tonnes | F36: =SUMIFS('Log Sales Data'!$I:$I,'Log Sales Data'!$C:$C,$B$2,'Log Sales Data'!$D:$D,$B36,'Log Sales Data'!$G:$G,$A36) -> 0 | G36: =IFERROR(H36/F36,"0") -> 0 | H36: =SUM(J36:U36) -> 0 | J36: =SUMIFS('Log Sales Data'!$M:$M,'Log Sales Data'!$B:$B,J$19,'Log Sales Data'!$C:$C,$B$2,'Log Sales Data'!$D:$D,$B36,'Log Sales Data'!$G:$G,$A36) -> 0 | K36: =SUMIFS('Log Sales Data'!$M:$M,'Log Sales Data'!$B:$B,K$19,'Log Sales Data'!$C:$C,$B$2,'Log Sales Data'!$D:$D,$B36,'Log Sales Data'!$G:$G,$A36) -> 0 | L36: =SUMIFS('Log Sales Data'!$M:$M,'Log Sales Data'!$B:$B,L$19,'Log Sales Data'!$C:$C,$B$2,'Log Sales Data'!$D:$D,$B36,'Log Sales Data'!$G:$G,$A36) -> 0 | M36: =SUMIFS('Log Sales Data'!$M:$M,'Log Sales Data'!$B:$B,M$19,'Log Sales Data'!$C:$C,$B$2,'Log Sales Data'!$D:$D,$B36,'Log Sales Data'!$G:$G,$A36) -> 0 | N36: =SUMIFS('Log Sales Data'!$M:$M,'Log Sales Data'!$B:$B,N$19,'Log Sales Data'!$C:$C,$B$2,'Log Sales Data'!$D:$D,$B36,'Log Sales Data'!$G:$G,$A36) -> 0 | O36: =SUMIFS('Log Sales Data'!$M:$M,'Log Sales Data'!$B:$B,O$19,'Log Sales Data'!$C:$C,$B$2,'Log Sales Data'!$D:$D,$B36,'Log Sales Data'!$G:$G,$A36) -> 0 | P36: =SUMIFS('Log Sales Data'!$M:$M,'Log Sales Data'!$B:$B,P$19,'Log Sales Data'!$C:$C,$B$2,'Log Sales Data'!$D:$D,$B36,'Log Sales Data'!$G:$G,$A36) -> 0 | Q36: =SUMIFS('Log Sales Data'!$M:$M,'Log Sales Data'!$B:$B,Q$19,'Log Sales Data'!$C:$C,$B$2,'Log Sales Data'!$D:$D,$B36,'Log Sales Data'!$G:$G,$A36) -> 0 | ... U36: =SUMIFS('Log Sales Data'!$M:$M,'Log Sales Data'!$B:$B,U$19,'Log Sales Data'!$C:$C,$B$2,'Log Sales Data'!$D:$D,$B36,'Log Sales Data'!$G:$G,$A36) -> 0
